Workbook

Sheet LNO-CCSD(T)-def2nZVP
A1: MOBH35 Revised Reference values from acs.jctc.9b01266 DLPNO-CCSD(T)/def2-{T,Q}ZVPP + (DLPNO-T1 - DLPNO-T0/def2TZVPP) | D1: LNO-CCSD(T)/def2-SV(P) with lcorthr=Tight with standard options | V1: LNO-CCSD(T) - CCSD(T) [MRCC - Ψ4] | AA1: DIFFERENCES OF DIFFERENCES | AE1: LNO-CCSD(T)/def2-SV(P) with lcorthr=Tight+ w/ wpairtol=1e-6 | AW1: LNO-CCSD(T) - CCSD(T) [MRCC - Ψ4] | BB1: DIFFERENCES OF DIFFERENCES | BF1: LNO-CCSD(T)/def2-SV(P) with lcorthr=Normal w/ wpairtol=1e-5 | BY1: LNO-CCSD(T) - CCSD(T) [MRCC - Ψ4] | CD1: DIFFERENCES OF DIFFERENCES | CH1: LNO-CCSD(T)/def2-SV(P) with lcorthr=Normal w/ wpairtol=1e-6 | DA1: LNO-CCSD(T) - CCSD(T) [MRCC - Ψ4] | DF1: DIFFERENCES OF DIFFERENCES | DJ1: LNO-CCSD(T)/def2-SV(P) with lcorthr=vTight | EC1: LNO-CCSD(T) - CCSD(T) [MRCC - Ψ4] | EH1: DIFFERENCES OF DIFFERENCES | EK1: LNO-CCSD(T)/def2-SVP with lcorthr=Tight with standard options | FM1: LNO-CCSD(T)/def2-SVP with lcorthr=Tight+ w/ wpairtol=1e-6 | GF1: LNO-CCSD(T) - CCSD(T) [MRCC - Ψ4] | GO1: LNO-CCSD(T)/def2-SVP with lcorthr=Normal w/ wpairtol=1e-5 | HH1: LNO-CCSD(T) - CCSD(T) [MRCC - Ψ4] | HQ1: LNO-CCSD(T)/def2-SVP with lcorthr=Normal w/ wpairtol=1e-6 | IK1: LNO-CCSD(T) - CCSD(T) [MRCC - Ψ4] | IS1: LNO-CCSD(T)/def2-SVP with lcorthr=vTight | JM1: LNO-CCSD(T) - CCSD(T) [MRCC - Ψ4] | JT1: LNO-CCSD(T)/pwCVTZ | JV1: LNO-CCSD(T)/cc-pVTZ-PP | JX1: LNO-CCSD(T)/def2-TZVPP with lcorthr=Tight+ w/ wpairtol=1e-6 | KX1: LNO-CCSD(T)/pwCVTZ | KZ1: LNO-CCSD(T)/pVTZ | LH1: DLPNO Tight TZVP | LK1: DLPNO Tight TZVP | LP1: LNO-CCSD(T)/def2-TZVPP with lcorthr=Tight (standard) w/ wpairtol=1e-5 | MJ1: LNO-CCSD(T)/def2-TZVPP with lcorthr=Normal w/ wpairtol=1e-5 | NE1: LNO-CCSD(T)/def2-TZVPP with lcorthr=Normal w/ wpairtol=1e-6 | NZ1: LNO-CCSD(T)/def2-QZVPP with lcorthr=Normal | OT1: LNO-CCSD(T)/def2-QZVPP with lcorthr=Tight (standard) wpairtol=3e-6 | PN1: a34 | PO1: Best estimate calculation | PX1: Best estimate calculation [CCSD component; def2-TZVPP and def2-QZVPP w/ Tight] | QH1: LNO-CCSD(T)/def2-TZVPP with lcorthr=Tight (standard) w/ wpairtol=3e-6 and FROZEN (n-1)sp | RB1: LNO-CCSD(T)/def2-QZVPP with lcorthr=Tight (standard) w/ wpairtol=3e-6 and FROZEN (n-1)sp
KJ2: RIMP2/def2-TZVPP | KL2: Css,1/3, Cos,1.2, | KM2: Css,0, Cos,1.3, | PN2: 7.88 | PO2: =1/(EXP(PN2*(SQRT(4)-SQRT(3)))-1) -> 0.13773869 | PP2: Schwenke coeffs. | PQ2: =1/((4/3)^2.97-1) -> 0.74074019 | PR2: =1/((3/2)^2.4-1) -> 0.6074678 | PX2: 0.13773869 | PY2: Schwenke coeffs. | PZ2: 0.74074019 | QA2: 0.6074678
C3: Species | D3: E_HF | E3: E_LNO_CCSD_T_with_mp2_weak_pairs | F3: E_LNO_CCSD_T | G3: E_LNO_CCSD_with_mp2_weak_pairs | H3: E_LNO_CCSD | I3: E_LNO_MP2_with_mp2_weak_pairs | J3: E_LNO_MP2 | L3: ΔE HF | M3: ΔE LNO-MP2 | N3: ΔE LNO-MP2+MP2 | O3: ΔE LNO-CCSD | P3: ΔE LNO-CCSD+MP2 | Q3: ΔE LNO-CCSD(T) | R3: ΔΕ LNO-CCSD(T)+MP2 | S3: CCSD(T)-MP2 | T3: . (T) | V3: ΔSCF | W3: ∆MP2 | X3: ∆CCSD | Y3: ∆CCSD(T) | Z3: ΔLNO-CCSD(T)-DLPNO-CCSD(T1) /def2-SV(P) | AA3: ∆CCSD - ∆SCF | AB3: ∆∆(T) | AD3: Species | AE3: E_HF | AF3: E_LNO_CCSD_T_with_mp2_weak_pairs | AG3: E_LNO_CCSD_T | AH3: E_LNO_CCSD_with_mp2_weak_pairs | AI3: E_LNO_CCSD | AJ3: E_LNO_MP2_with_mp2_weak_pairs | AK3: E_LNO_MP2 | AM3: ΔE HF | AN3: ΔE LNO-MP2 | AO3: ΔE LNO-MP2+MP2 | AP3: ΔE LNO-CCSD | AQ3: ΔE LNO-CCSD+MP2 | AR3: ΔE LNO-CCSD(T) | AS3: ΔΕ LNO-CCSD(T)+MP2 | AT3: CCSD(T)-MP2 | AU3: . (T) | AW3: ΔSCF | AX3: ∆MP2 | AY3: ∆CCSD | AZ3: ∆CCSD(T) | BA3: ΔLNO-CCSD(T)-DLPNO-CCSD(T1) /def2-SV(P) | BB3: ∆CCSD - ∆SCF | BC3: ∆∆(T) | BE3: Species | BF3: E_HF | BG3: E_LNO_CCSD_T_with_mp2_weak_pairs | BH3: E_LNO_CCSD_T | BI3: E_LNO_CCSD_with_mp2_weak_pairs | BJ3: E_LNO_CCSD | BK3: E_LNO_MP2_with_mp2_weak_pairs | BL3: Ecorr_mp2_weak_pairs | BM3: E_LNO_MP2 | BO3: ΔE HF | BP3: ΔE LNO-MP2 | BQ3: ΔE LNO-MP2+MP2 | BR3: ΔE LNO-CCSD | BS3: ΔE LNO-CCSD+MP2 | BT3: ΔE LNO-CCSD(T) | BU3: ΔΕ LNO-CCSD(T)+MP2 | BV3: CCSD(T)-MP2 | BW3: . (T) | BX3: Tight+-Normal (T) | BY3: ΔSCF | BZ3: ∆MP2 | CA3: ∆CCSD | CB3: ∆CCSD(T) | CC3: ΔLNO-CCSD(T)-DLPNO-CCSD(T1) /def2-sv(p) | CD3: ∆CCSD - ∆SCF | CE3: ∆∆(T) | CG3: Species | CH3: E_HF | CI3: E_LNO_CCSD_T_with_mp2_weak_pairs | CJ3: E_LNO_CCSD_T | CK3: E_LNO_CCSD_with_mp2_weak_pairs | CL3: E_LNO_CCSD | CM3: E_LNO_MP2_with_mp2_weak_pairs | CN3: Ecorr_mp2_weak_pairs | CO3: E_LNO_MP2 | CQ3: ΔE HF | CR3: ΔE LNO-MP2 | CS3: ΔE LNO-MP2+MP2 | CT3: ΔE LNO-CCSD | CU3: ΔE LNO-CCSD+MP2 | CV3: ΔE LNO-CCSD(T) | CW3: ΔΕ LNO-CCSD(T)+MP2 | CX3: CCSD(T)-MP2 | CY3: . (T) | CZ3: Normal(tight+)-Normal (T) | DA3: ΔSCF | DB3: ∆MP2 | DC3: ∆CCSD | DD3: ∆CCSD(T) | DE3: ΔLNO-CCSD(T)-DLPNO-CCSD(T1) /def2-SV(P) | DF3: ∆CCSD - ∆SCF | DG3: ∆∆(T) | DI3: Species | DJ3: E_HF | DK3: E_LNO_CCSD_T_with_mp2_weak_pairs | DL3: E_LNO_CCSD_T | DM3: E_LNO_CCSD_with_mp2_weak_pairs | DN3: E_LNO_CCSD | DO3: E_LNO_MP2_with_mp2_weak_pairs | DP3: Ecorr_mp2_weak_pairs | DQ3: E_LNO_MP2 | DS3: ΔE HF | DT3: ΔE LNO-MP2 | DU3: ΔE LNO-MP2+MP2 | DV3: ΔE LNO-CCSD | DW3: ΔE LNO-CCSD+MP2 | DX3: ΔE LNO-CCSD(T) | DY3: ΔΕ LNO-CCSD(T)+MP2 | DZ3: CCSD(T)-MP2 | EA3: . (T) | EB3: Verytight-Tight (T) | EC3: ΔSCF | ED3: ∆MP2 | EE3: ∆CCSD | EF3: ∆CCSD(T) | EG3: ΔLNO-CCSD(T)-DLPNO-CCSD(T1) /def2-SV(P) | EH3: ∆CCSD - ∆SCF | EI3: ∆∆(T) | EK3: FILE_NAME | EL3: E_HF | EM3: E_LNO_CCSD_T_with_mp2_weak_pairs | EN3: E_LNO_CCSD_T | EO3: E_LNO_CCSD_with_mp2_weak_pairs | EP3: E_LNO_CCSD | EQ3: E_LNO_MP2_with_mp2_weak_pairs | ER3: Ecorr_with_mp2_weak_pairs | ES3: E_LNO_MP2 | EU3: ΔE HF | EV3: ΔE LNO-MP2 | EW3: ΔE LNO-MP2+MP2 | EX3: ΔE LNO-CCSD | EY3: ΔE LNO-CCSD+MP2 | EZ3: ΔE LNO-CCSD(T) | FA3: ΔΕ LNO-CCSD(T)+MP2 | FB3: CCSD(T)-MP2 | FC3: . (T) | FD3: ΔSCF | FE3: ∆MP2 | FF3: ∆CCSD | FG3: ∆CCSD(T) | FH3: ΔLNO-CCSD(T)-DLPNO-CCSD(T1) /def2-SVP | FI3: ∆CCSD - ∆SCF | FJ3: ∆∆(T) | FL3: Species | FM3: E_HF | FN3: E_LNO_CCSD_T_with_mp2_weak_pairs | FO3: E_LNO_CCSD_T | FP3: E_LNO_CCSD_with_mp2_weak_pairs | FQ3: E_LNO_CCSD | FR3: E_LNO_MP2_with_mp2_weak_pairs | FS3: Ecorr_mp2_weak_pairs | FT3: E_LNO_MP2 | FV3: ΔE HF | FW3: ΔE LNO-MP2 | FX3: ΔE LNO-MP2+MP2 | FY3: ΔE LNO-CCSD | FZ3: ΔE LNO-CCSD+MP2 | GA3: ΔE LNO-CCSD(T) | GB3: ΔΕ LNO-CCSD(T)+MP2 | GC3: CCSD(T)-MP2 | GD3: . (T) | GE3: ∆TAE(TZVPP) | GF3: ΔSCF | GG3: ∆MP2 | GH3: ∆CCSD | GI3: ∆CCSD(T) | GJ3: ΔLNO-CCSD(T)- DLPNO-CCSD(T1) /def2-SVP [GRIDXS2] | GK3: ∆CCSD - ∆SCF | GL3: ∆∆(T) | GN3: Species | GO3: E_HF | GP3: E_LNO_CCSD_T_with_mp2_weak_pairs | GQ3: E_LNO_CCSD_T | GR3: E_LNO_CCSD_with_mp2_weak_pairs | GS3: E_LNO_CCSD | GT3: E_LNO_MP2_with_mp2_weak_pairs | GU3: Ecorr_mp2_weak_pairs | GV3: E_LNO_MP2 | GX3: ΔE HF | GY3: ΔE LNO-MP2 | GZ3: ΔE LNO-MP2+MP2 | HA3: ΔE LNO-CCSD | HB3: ΔE LNO-CCSD+MP2 | HC3: ΔE LNO-CCSD(T) | HD3: ΔΕ LNO-CCSD(T)+MP2 | HE3: CCSD(T)-MP2 | HF3: . (T) | HG3: Tight+-Normal (T) | HH3: ΔSCF | HI3: ∆MP2 | HJ3: ∆CCSD | HK3: ∆CCSD(T) | HL3: ΔLNO-CCSD(T)-DLPNO-CCSD(T1) /def2-svp [GRIDXS2] | HM3: ∆CCSD - ∆SCF | HN3: ∆∆(T) | HP3: Species | HQ3: E_HF | HR3: E_LNO_CCSD_T_with_mp2_weak_pairs | HS3: E_LNO_CCSD_T | HT3: E_LNO_CCSD_with_mp2_weak_pairs | HU3: E_LNO_CCSD | HV3: E_LNO_MP2_with_mp2_weak_pairs | HW3: Ecorr_with_mp2_weak_pairs | HX3: E_LNO_MP2 | HZ3: ΔE HF | IA3: ΔE LNO-MP2 | IB3: ΔE LNO-MP2+MP2 | IC3: ΔE LNO-CCSD | ID3: ΔE LNO-CCSD+MP2 | IE3: ΔE LNO-CCSD(T) | IF3: ΔΕ LNO-CCSD(T)+MP2 | IG3: CCSD(T)-MP2 | IH3: . (T) | II3: Normal(tight+)-Normal (T) | IJ3: ΔSCF | IK3: ∆MP2 | IL3: ∆CCSD | IM3: ∆CCSD(T) | IN3: ΔLNO-CCSD(T)- DLPNO-CCSD(T1) / def2-SVP | IO3: ∆CCSD - ∆SCF | IP3: ∆∆(T) | IR3: Species | IS3: E_HF | IT3: E_LNO_CCSD_T_with_mp2_weak_pairs | IU3: E_LNO_CCSD_T | IV3: E_LNO_CCSD_with_mp2_weak_pairs | IW3: E_LNO_CCSD | IX3: E_LNO_MP2_with_mp2_weak_pairs | IY3: Ecorr_with_mp2_weak_pairs | IZ3: E_LNO_MP2 | JB3: ΔE HF | JC3: ΔE LNO-MP2 | JD3: ΔE LNO-MP2+MP2 | JE3: ΔE LNO-CCSD | JF3: ΔE LNO-CCSD+MP2 | JG3: ΔE LNO-CCSD(T) | JH3: ΔΕ LNO-CCSD(T)+MP2 | JI3: CCSD(T)-MP2 | JJ3: . (T) | JK3: Verytight-Tight | JL3: ΔSCF | JM3: ∆MP2 | JN3: ∆CCSD | JO3: ∆CCSD(T) | JP3: ΔLNO-CCSD(T)- DLPNO-CCSD(T1) / def2-SVP | JQ3: ∆CCSD - ∆SCF | JR3: ∆∆(T) | JT3: LNO-CCSD(T) pwCVTZ(n-1)sp | JU3: LNO-CCSD(T) pwCVTZ (n-1)sp frozen | JV3: LNO-CCSD(T) cc-pVTZ-PP frozen | JX3: Species | JY3: E_HF | JZ3: E_LNO_CCSD_T_with_mp2_weak_pairs | KA3: E_LNO_CCSD_T | KB3: E_LNO_CCSD_with_mp2_weak_pairs | KC3: E_LNO_CCSD | KD3: E_LNO_MP2_with_mp2_weak_pairs | KE3: Ecorr_mp2_weak_pairs | KF3: E_LNO_MP2 | KG3: DLPNO-CCSD TightPNO | KH3: Mark Iron old | KJ3: E2ss | KK3: E2_OS | KL3: E_SCS-MP2 | KM3: E_SOS-MP2 | KN3: ΔE HF | KO3: ΔE LNO-MP2 | KP3: ΔE SCS-MP2 | KQ3: ΔE SOS-MP2 | KR3: ΔE LNO-MP2+MP2 | KS3: ΔE LNO-CCSD | KT3: ΔE LNO-CCSD+MP2 | KU3: ΔE LNO-CCSD(T) | KV3: ΔΕ LNO-CCSD(T)+MP2 | KW3: CCSD(T)-MP2 | KX3: pwCVTZ(n-1)sp | KY3: ditto sp frozen | KZ3: pVTZ-PP sp frozen | LA3: . (T) | LB3: Δbasis (T) | LC3: ΔSCF MRCC from MOLPRO | LD3: total TZVPP - SVP | LH3: CCSD | LI3: diff | LJ3: diff+MP2weak | LK3: CCSD(T) | LL3: diff | LM3: diff+MP2weak | LN3: -∆basis cross-check | LP3: Species | LQ3: E_HF | LR3: E_LNO_CCSD_T_with_mp2_weak_pairs | LS3: E_LNO_CCSD_T | LT3: E_LNO_CCSD_with_mp2_weak_pairs | LU3: E_LNO_CCSD | LV3: E_LNO_MP2_with_mp2_weak_pairs | LW3: Ecorr_mp2_weak_pairs | LX3: E_LNO_MP2 | LZ3: ΔE HF | MA3: ΔE LNO-MP2 | MB3: ΔE LNO-MP2+MP2 | MC3: ΔE LNO-CCSD | MD3: ΔE LNO-CCSD+MP2 | ME3: ΔE LNO-CCSD(T) | MF3: ΔΕ LNO-CCSD(T)+MP2 | MG3: CCSD(T)-MP2 | MH3: . (T) | MJ3: Species | MK3: E_HF | ML3: E_LNO_CCSD_T_with_mp2_weak_pairs | MM3: E_LNO_CCSD_T | MN3: E_LNO_CCSD_with_mp2_weak_pairs | MO3: E_LNO_CCSD | MP3: E_LNO_MP2_with_mp2_weak_pairs | MQ3: Ecorr_mp2_weak_pairs | MR3: E_LNO_MP2 | MT3: ΔE HF | MU3: ΔE LNO-MP2 | MV3: ΔE LNO-MP2+MP2 | MW3: ΔE LNO-CCSD | MX3: ΔE LNO-CCSD+MP2 | MY3: ΔE LNO-CCSD(T) | MZ3: ΔΕ LNO-CCSD(T)+MP2 | NA3: CCSD(T)-MP2 | NB3: . (T) | NC3: Tight-Normal (T) | NE3: Species | NF3: E_HF | NG3: E_LNO_CCSD_T_with_mp2_weak_pairs | NH3: E_LNO_CCSD_T | NI3: E_LNO_CCSD_with_mp2_weak_pairs | NJ3: E_LNO_CCSD | NK3: E_LNO_MP2_with_mp2_weak_pairs | NL3: Ecorr_mp2_weak_pairs | NM3: E_LNO_MP2 | NO3: ΔE HF | NP3: ΔE LNO-MP2 | NQ3: ΔE LNO-MP2+MP2 | NR3: ΔE LNO-CCSD | NS3: ΔE LNO-CCSD+MP2 | NT3: ΔE LNO-CCSD(T) | NU3: ΔΕ LNO-CCSD(T)+MP2 | NV3: CCSD(T)-MP2 | NW3: . (T) | NX3: Normal(tight+)-Normal (T) | NZ3: Species | OA3: E_HF | OB3: E_LNO_CCSD_T_with_mp2_weak_pairs | OC3: E_LNO_CCSD_T | OD3: E_LNO_CCSD_with_mp2_weak_pairs | OE3: E_LNO_CCSD | OF3: E_LNO_MP2_with_mp2_weak_pairs | OG3: Ecorr_mp2_weak_pairs | OH3: E_LNO_MP2 | OJ3: ΔE HF | OK3: ΔE LNO-MP2 | OL3: ΔE LNO-MP2+MP2 | OM3: ΔE LNO-CCSD | ON3: ΔE LNO-CCSD+MP2 | OO3: ΔE LNO-CCSD(T) | OP3: ΔΕ LNO-CCSD(T)+MP2 | OQ3: CCSD(T)-MP2 | OR3: . (T) | OT3: Species | OU3: E_HF | OV3: E_LNO_CCSD_T_with_mp2_weak_pairs | OW3: E_LNO_CCSD_T | OX3: E_LNO_CCSD_with_mp2_weak_pairs | OY3: E_LNO_CCSD | OZ3: E_LNO_MP2_with_mp2_weak_pairs | PA3: Ecorr_mp2_weak_pairs | PB3: E_LNO_MP2 | PD3: ΔE HF | PE3: ΔE LNO-MP2 | PF3: ΔE LNO-MP2+MP2 | PG3: ΔE LNO-CCSD | PH3: ΔE LNO-CCSD+MP2 | PI3: ΔE LNO-CCSD(T) | PJ3: ΔΕ LNO-CCSD(T)+MP2 | PK3: CCSD(T)-MP2 | PL3: . (T) | PO3: ∆basisSCF | PP3: ∆LNO-CCSD | PQ3: ∆CORRbasis CCSD | PR3: ∆CORRbasis Triples | PS3: ∆CBS SCF+CCSD | PT3: ∆CBS (T) | PU3: canonical - LNOtight / def2-SVP | PV3: BEST ESTIMATE | PX3: ∆basisSCF | PY3: ∆LNO-CCSD | PZ3: ∆CORRbasis CCSD | QA3: ∆CORRbasis Triples | QB3: ∆CBS SCF+CCSD | QC3: ∆CBS (T) | QD3: canonical - LNOtight / def2-SVP | QE3: BEST ESTIMATE | QH3: Species | QI3: E_HF | QJ3: E_LNO_CCSD_T_with_mp2_weak_pairs | QK3: E_LNO_CCSD_T | QL3: E_LNO_CCSD_with_mp2_weak_pairs | QM3: E_LNO_CCSD | QN3: E_LNO_MP2_with_mp2_weak_pairs | QO3: Ecorr_mp2_weak_pairs | QP3: E_LNO_MP2 | QR3: ΔE HF | QS3: ΔE LNO-MP2 | QT3: ΔE LNO-MP2+MP2 | QU3: ΔE LNO-CCSD | QV3: ΔE LNO-CCSD+MP2 | QW3: ΔE LNO-CCSD(T) | QX3: ΔΕ LNO-CCSD(T)+MP2 | QY3: CCSD(T)-MP2 | QZ3: . (T) | RB3: Species | RC3: E_HF | RD3: E_LNO_CCSD_T_with_mp2_weak_pairs | RE3: E_LNO_CCSD_T | RF3: E_LNO_CCSD_with_mp2_weak_pairs | RG3: E_LNO_CCSD | RH3: E_LNO_MP2_with_mp2_weak_pairs | RI3: Ecorr_mp2_weak_pairs | RJ3: E_LNO_MP2 | RL3: ΔE HF | RM3: ΔE LNO-MP2 | RN3: ΔE LNO-MP2+MP2 | RO3: ΔE LNO-CCSD | RP3: ΔE LNO-CCSD+MP2 | RQ3: ΔE LNO-CCSD(T) | RR3: ΔΕ LNO-CCSD(T)+MP2 | RS3: CCSD(T)-MP2 | RT3: . (T)
A4: 26.03 | C4: 01_end | D4: -1852.326 | E4: -1856.4935 | F4: -1856.4806 | G4: -1856.3313 | H4: -1856.3248 | I4: -1856.1193 | J4: -1856.1064 | K4: ∆E#fwd | L4: =627.5095*(D6-D5) -> 43.887969 | M4: =627.5095*(J6-J5) -> 28.148782 | N4: =627.5095*(I6-I5) -> 28.266525 | O4: =627.5095*(H6-H5) -> 33.200145 | P4: =627.5095*(G6-G5) -> 33.259016 | Q4: =627.5095*(F6-F5) -> 30.871739 | R4: =627.5095*(E6-E5) -> 30.989482 | S4: =R4-N4 -> 2.7229569 | T4: =R4-P4 -> -2.2695343 | V4: =L4-'CCSD(T)'!BV4 -> -0.0015012099 | W4: =N4-'CCSD(T)'!BW4 -> -0.049669154 | X4: =P4-'CCSD(T)'!BX4 -> -0.16742179 | Y4: =R4-'CCSD(T)'!BY4 -> -0.045154475 | Z4: =R4-'DLPNO-CCSD(T1 or T0)'!CT3 -> -0.13340747 | AA4: =X4-V4 -> -0.16592058 | AB4: =Y4-X4 -> 0.12226732 | AD4: 01_end | AE4: -1852.326 | AF4: -1856.4937 | AG4: -1856.481 | AH4: -1856.3315 | AI4: -1856.3251 | AJ4: -1856.1196 | AK4: -1856.1069 | AL4: ∆E#fwd | AM4: =627.5095*(AE6-AE5) -> 43.887969 | AN4: =627.5095*(AK6-AK5) -> 28.15577 | AO4: =627.5095*(AJ6-AJ5) -> 28.276181 | AP4: =627.5095*(AI6-AI5) -> 33.203304 | AQ4: =627.5095*(AH6-AH5) -> 33.26351 | AR4: =627.5095*(AG6-AG5) -> 30.870105 | AS4: =627.5095*(AF6-AF5) -> 30.990516 | AT4: =AS4-AO4 -> 2.7143346 | AU4: =AS4-AQ4 -> -2.272994 | AW4: =AM4-'CCSD(T)'!BV4 -> -0.001501235 | AX4: =AO4-'CCSD(T)'!BW4 -> -0.040012975 | AY4: =AQ4-'CCSD(T)'!BX4 -> -0.16292819 | AZ4: =AS4-'CCSD(T)'!BY4 -> -0.04412059 | BA4: =AS4-'DLPNO-CCSD(T1 or T0)'!CT3 -> -0.13237359 | BB4: =AY4-AW4 -> -0.16142696 | BC4: =AZ4-AY4 -> 0.1188076 | BE4: 01_end | BF4: -1852.326 | BG4: -1856.4943 | BH4: -1856.4597 | BI4: -1856.3277 | BJ4: -1856.3104 | BK4: -1856.1181 | BL4: -0.034579473 | BM4: =BK4-BL4 -> -1856.0835 | BN4: ∆E#fwd | BO4: =627.5095*(BF6-BF5) -> 43.887969 | BP4: =627.5095*(BM6-BM5) -> 27.967582 | BQ4: =627.5095*(BK6-BK5) -> 28.19795 | BR4: =627.5095*(BJ6-BJ5) -> 32.904649 | BS4: =627.5095*(BI6-BI5) -> 33.019833 | BT4: =627.5095*(BH6-BH5) -> 30.698486 | BU4: =627.5095*(BG6-BG5) -> 30.928854 | BV4: =BU4-BQ4 -> 2.7309043 | BW4: =BU4-BS4 -> -2.0909792 | BX4: =AU4-BW4 -> -0.18201485 | BY4: =BO4-'CCSD(T)'!BV4 -> -0.0015012099 | BZ4: =BQ4-'CCSD(T)'!BW4 -> -0.11824417 | CA4: =BS4-'CCSD(T)'!BX4 -> -0.40660458 | CB4: =BU4-'CCSD(T)'!BY4 -> -0.10578213 | CC4: =BU4-'DLPNO-CCSD(T1 or T0)'!CT3 -> -0.19403513 | CD4: =CA4-BY4 -> -0.40510337 | CE4: =CB4-CA4 -> 0.30082245 | CG4: 01_end | CH4: -1852.326 | CI4: -1856.4953 | CJ4: -1856.4613 | CK4: -1856.3287 | CL4: -1856.3118 | CM4: -1856.1193 | CN4: -0.033970896 | CO4: =CM4-CN4 -> -1856.0854 | CP4: ∆E#fwd | CQ4: =627.5095*(CH6-CH5) -> 43.887969 | CR4: =627.5095*(CO6-CO5) -> 27.986221 | CS4: =627.5095*(CM6-CM5) -> 28.18744 | CT4: =627.5095*(CL6-CL5) -> 32.948366 | CU4: =627.5095*(CK6-CK5) -> 33.048976 | CV4: =627.5095*(CJ6-CJ5) -> 30.746307 | CW4: =627.5095*(CI6-CI5) -> 30.947526 | CX4: =CW4-CS4 -> 2.760086 | CY4: =CW4-CU4 -> -2.1014498 | CZ4: =CY4-BW4 -> -0.010470599 | DA4: =CQ4-'CCSD(T)'!BV4 -> -0.0015012161 | DB4: =CS4-'CCSD(T)'!BW4 -> -0.12875428 | DC4: =CU4-'CCSD(T)'!BX4 -> -0.37746237 | DD4: =CW4-'CCSD(T)'!BY4 -> -0.08711052 | DE4: =CW4-'DLPNO-CCSD(T1 or T0)'!CT3 -> -0.17536352 | DF4: =DC4-DA4 -> -0.37596115 | DG4: =DD4-DC4 -> 0.29035185 | DI4: 01_end | DJ4: -1852.326 | DK4: -1856.4926 | DL4: -1856.4889 | DM4: -1856.332 | DN4: -1856.3302 | DO4: -1856.1199 | DP4: -0.0036721738 | DQ4: =DO4-DP4 -> -1856.1162 | DR4: ∆E#fwd | DS4: =627.5095*(DJ6-DJ5) -> 43.887969 | DT4: =627.5095*(DQ6-DQ5) -> 28.315524 | DU4: =627.5095*(DO6-DO5) -> 28.313391 | DV4: =627.5095*(DN6-DN5) -> 33.374776 | DW4: =627.5095*(DM6-DM5) -> 33.37371 | DX4: =627.5095*(DL6-DL5) -> 31.01398 | DY4: =627.5095*(DK6-DK5) -> 31.011847 | DZ4: =DY4-DU4 -> 2.6984558 | EA4: =DY4-DW4 -> -2.3618628 | EB4: =EA4-T4 -> -0.092328523 | EC4: =DS4-'CCSD(T)'!BV4 -> -0.0015011973 | ED4: =DU4-'CCSD(T)'!BW4 -> -0.0028026969 | EE4: =DW4-'CCSD(T)'!BX4 -> -0.052727911 | EF4: =DY4-'CCSD(T)'!BY4 -> -0.022789114 | EG4: =DY4-'DLPNO-CCSD(T1 or T0)'!CT3 -> -0.11104211 | EH4: =EE4-EC4 -> -0.051226714 | EI4: =EF4-EE4 -> 0.029938797 | EK4: 01_end | EL4: -1852.439 | EM4: -1856.9216 | EN4: -1856.9079 | EO4: -1856.7445 | EP4: -1856.7377 | EQ4: -1856.5242 | ER4: -0.013679538 | ES4: =EQ4-ER4 -> -1856.5105 | ET4: ∆E#fwd | EU4: =627.5095*(EL6-EL5) -> 40.985735 | EV4: =627.5095*(ES6-ES5) -> 24.314894 | EW4: =627.5095*(EQ6-EQ5) -> 24.414897 | EX4: =627.5095*(EP6-EP5) -> 29.40981 | EY4: =627.5095*(EO6-EO5) -> 29.459812 | EZ4: =627.5095*(EN6-EN5) -> 26.94828 | FA4: =627.5095*(EM6-EM5) -> 27.048284 | FB4: =FA4-EW4 -> 2.6333863 | FC4: =FA4-EY4 -> -2.4115287 | FD4: =EU4-'CCSD(T)'!BB4 -> -0.0028887587 | FE4: =EW4-'CCSD(T)'!BC4 -> -0.0056683879 | FF4: =EY4-'CCSD(T)'!CH4 -> -0.13489842 | FG4: =FA4-'CCSD(T)'!CI4 -> -0.015148294 | FH4: =FA4-'DLPNO-CCSD(T1 or T0)'!AF3 -> -0.1378394 | FI4: =FF4-FD4 -> -0.13200967 | FJ4: =FG4-FF4 -> 0.11975013 | FL4: 01_end | FM4: -1852.439 | FN4: -1856.9218 | FO4: -1856.9082 | FP4: -1856.7447 | FQ4: -1856.738 | FR4: -1856.5245 | FS4: -0.013567072 | FT4: =FR4-FS4 -> -1856.5109 | FU4: ∆E#fwd | FV4: =627.5095*(FM6-FM5) -> 40.985735 | FW4: =627.5095*(FT6-FT5) -> 24.339563 | FX4: =627.5095*(FR6-FR5) -> 24.429121 | FY4: =627.5095*(FQ6-FQ5) -> 29.420192 | FZ4: =627.5095*(FP6-FP5) -> 29.464971 | GA4: =627.5095*(FO6-FO5) -> 26.967453 | GB4: =627.5095*(FN6-FN5) -> 27.057011 | GC4: =GB4-FX4 -> 2.6278894 | GD4: =GB4-FZ4 -> -2.4079607 | GE4: =LA4-GD4 -> -0.37701308 | GF4: =FV4-'CCSD(T)'!BB4 -> -0.0028887712 | GG4: =FX4-'CCSD(T)'!BC4 -> 0.0085555771 | GH4: =FZ4-'CCSD(T)'!BD4 -> -0.12973935 | GI4: =GB4-'CCSD(T)'!BE4 -> -0.0064212054 | GJ4: =GB4-'DLPNO-CCSD(T1 or T0)'!O3 -> -0.32102228 | GK4: =GH4-GF4 -> -0.12685058 | GL4: =GI4-GH4 -> 0.12331814 | GN4: 01_end | GO4: -1852.439 | GP4: -1856.9224 | GQ4: -1856.8845 | GR4: -1856.7408 | GS4: -1856.7218 | GT4: -1856.5227 | GU4: -0.037871189 | GV4: =GT4-GU4 -> -1856.4849 | GW4: ∆E#fwd | GX4: =627.5095*(GO6-GO5) -> 40.985735 | GY4: =627.5095*(GV6-GV5) -> 24.027126 | GZ4: =627.5095*(GT6-GT5) -> 24.27279 | HA4: =627.5095*(GS6-GS5) -> 29.062414 | HB4: =627.5095*(GR6-GR5) -> 29.185246 | HC4: =627.5095*(GQ6-GQ5) -> 26.709884 | HD4: =627.5095*(GP6-GP5) -> 26.955548 | HE4: =HD4-GZ4 -> 2.6827579 | HF4: =HD4-HB4 -> -2.2296981 | HG4: =GD4-HF4 -> -0.17826259 | HH4: =GX4-'CCSD(T)'!BB4 -> -0.0028887649 | HI4: =GZ4-'CCSD(T)'!BC4 -> -0.14777565 | HJ4: =HB4-'CCSD(T)'!BD4 -> -0.40946466 | HK4: =HD4-'CCSD(T)'!BE4 -> -0.10788393 | HL4: =HD4-'DLPNO-CCSD(T1 or T0)'!CT3 -> -4.1673412 | HM4: =HJ4-HH4 -> -0.4065759 | HN4: =HK4-HJ4 -> 0.30158073 | HP4: 01_end | HQ4: -1852.439 | HR4: -1856.9234 | HS4: -1856.8863 | HT4: -1856.7419 | HU4: -1856.7233 | HV4: -1856.5241 | HW4: -0.037112676 | HX4: =HV4-HW4 -> -1856.487 | HY4: ∆E#fwd | HZ4: =627.5095*(HQ6-HQ5) -> 40.985735 | IA4: =627.5095*(HX6-HX5) -> 24.133203 | IB4: =627.5095*(HV6-HV5) -> 24.301834 | IC4: =627.5095*(HU6-HU5) -> 29.154423 | ID4: =627.5095*(HT6-HT5) -> 29.238738 | IE4: =627.5095*(HS6-HS5) -> 26.822988 | IF4: =627.5095*(HR6-HR5) -> 26.991619 | IG4: =IF4-IB4 -> 2.689785 | IH4: =IF4-ID4 -> -2.2471194 | II4: =IH4-HF4 -> -0.017421339 | IJ4: =HZ4-'CCSD(T)'!BB4 -> -0.0028887649 | IK4: =IB4-'CCSD(T)'!BC4 -> -0.11873181 | IL4: =ID4-'CCSD(T)'!BD4 -> -0.35597239 | IM4: =IF4-'CCSD(T)'!BE4 -> -0.071813004 | IN4: =IF4-'DLPNO-CCSD(T1 or T0)'!CT3 -> -4.1312703 | IO4: =IL4-IJ4 -> -0.35308363 | IP4: =IM4-IL4 -> 0.28415939 | IR4: 01_end | IS4: -1852.439 | IT4: -1856.9213 | IU4: -1856.9171 | IV4: -1856.7455 | IW4: -1856.7434 | IX4: -1856.5249 | IY4: -0.0042179316 | IZ4: =IX4-IY4 -> -1856.5206 | JA4: ∆E#fwd | JB4: =627.5095*(IS6-IS5) -> 40.985735 | JC4: =627.5095*(IZ6-IZ5) -> 24.425827 | JD4: =627.5095*(IX6-IX5) -> 24.424725 | JE4: =627.5095*(IW6-IW5) -> 29.538636 | JF4: =627.5095*(IV6-IV5) -> 29.538085 | JG4: =627.5095*(IU6-IU5) -> 27.038938 | JH4: =627.5095*(IT6-IT5) -> 27.037837 | JI4: =JH4-JD4 -> 2.6131112 | JJ4: =JH4-JF4 -> -2.5002489 | JK4: =JJ4-FC4 -> -0.088720205 | JL4: =JB4-'CCSD(T)'!BB4 -> -0.0028887649 | JM4: =JD4-'CCSD(T)'!BC4 -> 0.0041595466 | JN4: =JF4-'CCSD(T)'!BD4 -> -0.056625361 | JO4: =JH4-'CCSD(T)'!BE4 -> -0.025595436 | JP4: =JH4-'DLPNO-CCSD(T1 or T0)'!CT3 -> -4.0850527 | JQ4: =JN4-JL4 -> -0.053736597 | JR4: =JO4-JN4 -> 0.031029926 | JT4: -1859.1833 | JU4: -1858.839 | JV4: -1858.837 | JX4: 01_end | JY4: -1853.7027 | JZ4: -1859.0938 | KA4: -1859.0717 | KB4: -1858.8364 | KC4: -1858.8254 | KD4: -1858.6884 | KE4: -0.022075362 | KF4: =KD4-KE4 -> -1858.6663 | KG4: -1858.7197 | KH4: -1858.7197 | KI4: -1858.9658 | KJ4: -1.2469053 | KK4: -3.7390211 | KL4: =1.2*KK4+(1/3)*KJ4+JY4 -> -1858.6052 | KM4: =1.3*KK4+JY4 -> -1858.5635 | KN4: =627.5095*(JY6-JY5) -> 41.14991 | KO4: =627.5095*(KF6-KF5) -> 23.973243 | KP4: =627.5095*(KL6-KL5) -> 27.349453 | KQ4: =627.5095*(KM6-KM5) -> 29.111828 | KR4: =627.5095*(KD6-KD5) -> 23.888645 | KS4: =627.5095*(KC6-KC5) -> 29.577045 | KT4: =627.5095*(KB6-KB5) -> 29.534745 | KU4: =627.5095*(KA6-KA5) -> 26.83437 | KV4: =627.5095*(JZ6-JZ5) -> 26.749772 | KW4: =KV4-KR4 -> 2.861127 | KX4: =627.5095*(JT6-JT5) -> 26.54748 | KY4: =627.5095*(JU6-JU5) -> 28.536534 | KZ4: =627.5095*(JV6-JV5) -> 28.623518 | LA4: =KV4-KT4 -> -2.7849738 | LB4: =LA4-GD4 -> -0.37701308 | LC4: =KN4-'PNO-LCCSD(T)'!AB3 -> -0.003876465 | LD4: =KV4-GB4 -> -0.30723918 | LE4: =KX4-KV4 -> -0.20229179 | LF4: =KY4-KX4 -> 1.989054 | LG4: =AD4 -> 01_end | LH4: =627.5095*(KG6-KG5) -> 29.599155 | LI4: =KS4-LH4 -> -0.022110416 | LJ4: =KT4-LH4 -> -0.064409658 | LK4: =627.5095*(KI6-KI5) -> 26.878058 | LL4: =KU4-LK4 -> -0.043687883 | LM4: =KV4-LK4 -> -0.12828637 | LN4: =AP4-KS4 -> 3.6262597 | LP4: 01_end | LQ4: -1853.7027 | LR4: -1859.0935 | LS4: -1859.0712 | LT4: -1858.8362 | LU4: -1858.825 | LV4: -1858.688 | LW4: -0.022260182 | LX4: =LV4-LW4 -> -1858.6658 | LY4: ∆E#fwd | LZ4: =627.5095*(LQ6-LQ5) -> 41.14991 | MA4: =627.5095*(LX6-LX5) -> 23.977291 | MB4: =627.5095*(LV6-LV5) -> 23.892872 | MC4: =627.5095*(LU6-LU5) -> 29.578853 | MD4: =627.5095*(LT6-LT5) -> 29.536644 | ME4: =627.5095*(LS6-LS5) -> 26.836378 | MF4: =627.5095*(LR6-LR5) -> 26.751959 | MG4: =MF4-MB4 -> 2.8590872 | MH4: =MF4-MD4 -> -2.784685 | MJ4: 01_end | MK4: -1853.7027 | ML4: -1859.094 | MM4: -1859.0359 | MN4: -1858.8311 | MO4: -1858.802 | MP4: -1858.6861 | MQ4: -0.058075219 | MR4: =MP4-MQ4 -> -1858.628 | MS4: ∆E#fwd | MT4: =627.5095*(MK6-MK5) -> 41.14991 | MU4: =627.5095*(MR6-MR5) -> 23.843021 | MV4: =627.5095*(MP6-MP5) -> 23.836869 | MW4: =627.5095*(MO6-MO5) -> 29.344223 | MX4: =627.5095*(MN6-MN5) -> 29.341147 | MY4: =627.5095*(MM6-MM5) -> 26.77224 | MZ4: =627.5095*(ML6-ML5) -> 26.766087 | NA4: =MZ4-MV4 -> 2.9292182 | NB4: =MZ4-MX4 -> -2.5750596 | NC4: =LA4-NB4 -> -0.20991419 | NE4: 01_end | NF4: -1853.7027 | NG4: -1859.0954 | NH4: -1859.0382 | NI4: -1858.8326 | NJ4: -1858.8039 | NK4: -1858.6879 | NL4: -0.05726023 | NM4: =NK4-NL4 -> -1858.6306 | NN4: ∆E#fwd | NO4: =627.5095*(NF6-NF5) -> 41.14991 | NP4: =627.5095*(NM6-NM5) -> 23.873662 | NQ4: =627.5095*(NK6-NK5) -> 23.877165 | NR4: =627.5095*(NJ6-NJ5) -> 29.400593 | NS4: =627.5095*(NI6-NI5) -> 29.402345 | NT4: =627.5095*(NH6-NH5) -> 26.806423 | NU4: =627.5095*(NG6-NG5) -> 26.809926 | NV4: =NU4-NQ4 -> 2.9327606 | NW4: =NU4-NS4 -> -2.5924188 | NX4: =NW4-NB4 -> -0.01735926 | NZ4: 01_end | OA4: -1853.7622 | OB4: -1859.4597 | OC4: -1859.3776 | OD4: -1859.1666 | OE4: -1859.1256 | OF4: -1859.0767 | OG4: -0.082050956 | OH4: =OF4-OG4 -> -1858.9946 | OI4: ∆E#fwd | OJ4: =627.5095*(OA6-OA5) -> 41.179763 | OK4: =627.5095*(OH6-OH5) -> 23.576205 | OL4: =627.5095*(OF6-OF5) -> 23.240731 | OM4: =627.5095*(OE6-OE5) -> 29.084947 | ON4: =627.5095*(OD6-OD5) -> 28.91721 | OO4: =627.5095*(OC6-OC5) -> 26.47493 | OP4: =627.5095*(OB6-OB5) -> 26.139456 | OQ4: =OP4-OL4 -> 2.8987254 | OR4: =OP4-ON4 -> -2.7777542 | OT4: 01_end | OU4: -1853.7622 | OV4: -1859.4563 | OW4: -1859.4242 | OX4: -1859.1735 | OY4: -1859.1574 | OZ4: -1859.0786 | PA4: -0.032163635 | PB4: -1859.0465 | PC4: ∆E#fwd | PD4: 41.179762 | PE4: 23.467283 | PF4: 23.272028 | PG4: 29.158283 | PH4: 29.060656 | PI4: 26.36723 | PJ4: 26.171975 | PK4: 2.8999467 | PL4: -2.8886813 | PO4: =OJ4-MT4 -> 0.02985298 | PP4: =ON4-MX4 -> -0.42393611 | PQ4: =PP4-PO4 -> -0.45378909 | PR4: ='LNO-CCSD(T)-def2nZVP'!LB4 -> -0.37701308 | PS4: =PO$2*PO4+PQ$2*PQ4 -> -0.3320279 | PT4: =PR4*PR$2 -> -0.2290233 | PU4: =-'LNO-CCSD(T)-def2nZVP'!FA4+'CCSD(T)'!CI4 -> 0.015148294 | PV4: ='LNO-CCSD(T)-def2nZVP'!KV4+PS4+PT4+PU4 -> 26.203869 | PX4: 0.029852202 | PY4: -0.47598834 | PZ4: -0.50584054 | QA4: -0.37701308 | QB4: -0.37058462 | QC4: -0.2290233 | QD4: 0.015148294 | QE4: 26.165312 | QF4: =QE4-PV4 -> -0.038556712 | QH4: 01_end | QI4: -1853.7027 | QJ4: -1858.8461 | QK4: -1858.8256 | QL4: -1858.5979 | QM4: -1858.5877 | QN4: -1858.4572 | QO4: -0.020423186 | QP4: =QN4-QO4 -> -1858.4368 | QQ4: ∆E#fwd | QR4: =627.5095*(QI6-QI5) -> 41.14991 | QS4: =627.5095*(QP6-QP5) -> 26.591363 | QT4: =627.5095*(QN6-QN5) -> 26.524629 | QU4: =627.5095*(QM6-QM5) -> 31.418368 | QV4: =627.5095*(QL6-QL5) -> 31.385002 | QW4: =627.5095*(QK6-QK5) -> 28.892702 | QX4: =627.5095*(QJ6-QJ5) -> 28.825969 | QY4: =QX4-QT4 -> 2.3013392 | QZ4: =QX4-QV4 -> -2.5590332 | RB4: 01_end | RC4: -1853.7622 | RD4: -1859.1571 | RE4: -1859.1272 | RF4: -1858.8874 | RG4: -1858.8725 | RH4: -1858.8037 | RI4: -0.02990687 | RJ4: =RH4-RI4 -> -1858.7738 | RK4: ∆E#fwd | RL4: =627.5095*(RC6-RC5) -> 41.179763 | RM4: =627.5095*(RJ6-RJ5) -> 26.575196 | RN4: =627.5095*(RH6-RH5) -> 26.433229 | RO4: =627.5095*(RG6-RG5) -> 31.462281 | RP4: =627.5095*(RF6-RF5) -> 31.391298 | RQ4: =627.5095*(RE6-RE5) -> 28.901617 | RR4: =627.5095*(RD6-RD5) -> 28.75965 | RS4: =RR4-RN4 -> 2.3264207 | RT4: =RR4-RP4 -> -2.6316477
A5: 15.4 | C5: 01_start | D5: -1852.3368 | E5: -1856.5147 | F5: -1856.5014 | G5: -1856.3508 | H5: -1856.3442 | I5: -1856.1433 | J5: -1856.13 | K5: ∆E#rev | L5: =627.5095*(D6-D4) -> 37.146076 | M5: =627.5095*(J6-J4) -> 13.35097 | N5: =627.5095*(I6-I4) -> 13.216553 | O5: =627.5095*(H6-H4) -> 21.048286 | P5: =627.5095*(G6-G4) -> 20.981077 | Q5: =627.5095*(F6-F4) -> 17.825763 | R5: =627.5095*(E6-E4) -> 17.691345 | S5: =R5-N5 -> 4.4747926 | T5: =R5-P5 -> -3.2897319 | V5: =L5-'CCSD(T)'!BV5 -> -0.00033706677 | W5: =N5-'CCSD(T)'!BW5 -> -0.013377488 | X5: =P5-'CCSD(T)'!BX5 -> -0.21661958 | Y5: =R5-'CCSD(T)'!BY5 -> -0.073476012 | Z5: =R5-'DLPNO-CCSD(T1 or T0)'!CT4 -> -0.18421981 | AA5: =X5-V5 -> -0.21628252 | AB5: =Y5-X5 -> 0.14314357 | AD5: 01_start | AE5: -1852.3368 | AF5: -1856.5149 | AG5: -1856.5017 | AH5: -1856.351 | AI5: -1856.3445 | AJ5: -1856.1435 | AK5: -1856.1304 | AL5: ∆E#rev | AM5: =627.5095*(AE6-AE4) -> 37.146076 | AN5: =627.5095*(AK6-AK4) -> 13.383185 | AO5: =627.5095*(AJ6-AJ4) -> 13.236757 | AP5: =627.5095*(AI6-AI4) -> 21.066952 | AQ5: =627.5095*(AH6-AH4) -> 20.993738 | AR5: =627.5095*(AG6-AG4) -> 17.845948 | AS5: =627.5095*(AF6-AF4) -> 17.699519 | AT5: =AS5-AO5 -> 4.4627628 | AU5: =AS5-AQ5 -> -3.2942188 | AW5: =AM5-'CCSD(T)'!BV5 -> -0.00033709188 | AX5: =AO5-'CCSD(T)'!BW5 -> 0.0068263538 | AY5: =AQ5-'CCSD(T)'!BX5 -> -0.20395861 | AZ5: =AS5-'CCSD(T)'!BY5 -> -0.065301973 | BA5: =AS5-'DLPNO-CCSD(T1 or T0)'!CT4 -> -0.17604577 | BB5: =AY5-AW5 -> -0.20362151 | BC5: =AZ5-AY5 -> 0.13865663 | BE5: 01_start | BF5: -1852.3368 | BG5: -1856.5155 | BH5: -1856.4796 | BI5: -1856.3471 | BJ5: -1856.3292 | BK5: -1856.1419 | BL5: -0.035909793 | BM5: =BK5-BL5 -> -1856.106 | BN5: ∆E#rev | BO5: =627.5095*(BF6-BF4) -> 37.146076 | BP5: =627.5095*(BM6-BM4) -> 13.862511 | BQ5: =627.5095*(BK6-BK4) -> 13.258091 | BR5: =627.5095*(BJ6-BJ4) -> 21.10803 | BS5: =627.5095*(BI6-BI4) -> 20.80582 | BT5: =627.5095*(BH6-BH4) -> 18.195299 | BU5: =627.5095*(BG6-BG4) -> 17.590879 | BV5: =BU5-BQ5 -> 4.3327874 | BW5: =BU5-BS5 -> -3.2149413 | BX5: =AU5-BW5 -> -0.079277505 | BY5: =BO5-'CCSD(T)'!BV5 -> -0.00033707933 | BZ5: =BQ5-'CCSD(T)'!BW5 -> 0.028160924 | CA5: =BS5-'CCSD(T)'!BX5 -> -0.39187689 | CB5: =BU5-'CCSD(T)'!BY5 -> -0.17394276 | CC5: =BU5-'DLPNO-CCSD(T1 or T0)'!CT4 -> -0.28468655 | CD5: =CA5-BY5 -> -0.39153981 | CE5: =CB5-CA5 -> 0.21793414 | CG5: 01_start | CH5: -1852.3368 | CI5: -1856.5165 | CJ5: -1856.4814 | CK5: -1856.3483 | CL5: -1856.3307 | CM5: -1856.1433 | CN5: -0.035104986 | CO5: =CM5-CN5 -> -1856.1082 | CP5: ∆E#rev | CQ5: =627.5095*(CH6-CH4) -> 37.146076 | CR5: =627.5095*(CO6-CO4) -> 13.679999 | CS5: =627.5095*(CM6-CM4) -> 13.169564 | CT5: =627.5095*(CL6-CL4) -> 21.057031 | CU5: =627.5095*(CK6-CK4) -> 20.801813 | CV5: =627.5095*(CJ6-CJ4) -> 18.125861 | CW5: =627.5095*(CI6-CI4) -> 17.615427 | CX5: =CW5-CS5 -> 4.4458621 | CY5: =CW5-CU5 -> -3.186387 | CZ5: =CY5-BW5 -> 0.028554311 | DA5: =CQ5-'CCSD(T)'!BV5 -> -0.00033707305 | DB5: =CS5-'CCSD(T)'!BW5 -> -0.060365732 | DC5: =CU5-'CCSD(T)'!BX5 -> -0.39588319 | DD5: =CW5-'CCSD(T)'!BY5 -> -0.14939474 | DE5: =CW5-'DLPNO-CCSD(T1 or T0)'!CT4 -> -0.26013854 | DF5: =DC5-DA5 -> -0.39554612 | DG5: =DD5-DC5 -> 0.24648845 | DI5: 01_start | DJ5: -1852.3368 | DK5: -1856.5137 | DL5: -1856.51 | DM5: -1856.3516 | DN5: -1856.3497 | DO5: -1856.144 | DP5: -0.0037226802 | DQ5: =DO5-DP5 -> -1856.1403 | DR5: ∆E#rev | DS5: =627.5095*(DJ6-DJ4) -> 37.146076 | DT5: =627.5095*(DQ6-DQ4) -> 13.229264 | DU5: =627.5095*(DO6-DO4) -> 13.195437 | DV5: =627.5095*(DN6-DN4) -> 21.125561 | DW5: =627.5095*(DM6-DM4) -> 21.108648 | DX5: =627.5095*(DL6-DL4) -> 17.798211 | DY5: =627.5095*(DK6-DK4) -> 17.764385 | DZ5: =DY5-DU5 -> 4.5689471 | EA5: =DY5-DW5 -> -3.3442638 | EB5: =EA5-T5 -> -0.054531925 | EC5: =DS5-'CCSD(T)'!BV5 -> -0.00033704794 | ED5: =DU5-'CCSD(T)'!BW5 -> -0.034492693 | EE5: =DW5-'CCSD(T)'!BX5 -> -0.089048345 | EF5: =DY5-'CCSD(T)'!BY5 -> -0.00043669876 | EG5: =DY5-'DLPNO-CCSD(T1 or T0)'!CT4 -> -0.1111805 | EH5: =EE5-EC5 -> -0.088711297 | EI5: =EF5-EE5 -> 0.088611646 | EK5: 01_start | EL5: -1852.4497 | EM5: -1856.9424 | EN5: -1856.9283 | EO5: -1856.7636 | EP5: -1856.7566 | EQ5: -1856.548 | ER5: -0.014047594 | ES5: =EQ5-ER5 -> -1856.534 | ET5: ∆E#rev | EU5: =627.5095*(EL6-EL4) -> 34.291579 | EV5: =627.5095*(ES6-ES4) -> 9.5689781 | EW5: =627.5095*(EQ6-EQ4) -> 9.4380228 | EX5: =627.5095*(EP6-EP4) -> 17.558666 | EY5: =627.5095*(EO6-EO4) -> 17.493188 | EZ5: =627.5095*(EN6-EN4) -> 14.118687 | FA5: =627.5095*(EM6-EM4) -> 13.987732 | FB5: =FA5-EW5 -> 4.5497088 | FC5: =FA5-EY5 -> -3.5054567 | FD5: =EU5-'CCSD(T)'!BB5 -> -0.0040419456 | FE5: =EW5-'CCSD(T)'!BC5 -> 0.012873129 | FF5: =EY5-'CCSD(T)'!CH5 -> -0.20763382 | FG5: =FA5-'CCSD(T)'!CI5 -> -0.03498756 | FH5: =FA5-'DLPNO-CCSD(T1 or T0)'!AF4 -> -0.27726867 | FI5: =FF5-FD5 -> -0.20359187 | FJ5: =FG5-FF5 -> 0.17264626 | FL5: 01_start | FM5: -1852.4497 | FN5: -1856.9426 | FO5: -1856.9287 | FP5: -1856.7638 | FQ5: -1856.7568 | FR5: -1856.5483 | FS5: -0.013927731 | FT5: =FR5-FS5 -> -1856.5344 | FU5: ∆E#rev | FV5: =627.5095*(FM6-FM4) -> 34.291579 | FW5: =627.5095*(FT6-FT4) -> 9.5964808 | FX5: =627.5095*(FR6-FR4) -> 9.4597224 | FY5: =627.5095*(FQ6-FQ4) -> 17.574648 | FZ5: =627.5095*(FP6-FP4) -> 17.506269 | GA5: =627.5095*(FO6-FO4) -> 14.135397 | GB5: =627.5095*(FN6-FN4) -> 13.998639 | GC5: =GB5-FX5 -> 4.5389162 | GD5: =GB5-FZ5 -> -3.5076306 | GE5: =LA5-GD5 -> -0.40526999 | GF5: =FV5-'CCSD(T)'!BB5 -> -0.0040419079 | GG5: =FX5-'CCSD(T)'!BC5 -> 0.034572689 | GH5: =FZ5-'CCSD(T)'!BD5 -> -0.194553 | GI5: =GB5-'CCSD(T)'!BE5 -> -0.024080573 | GJ5: =GB5-'DLPNO-CCSD(T1 or T0)'!O4 -> -0.39137099 | GK5: =GH5-GF5 -> -0.19051109 | GL5: =GI5-GH5 -> 0.17047243 | GN5: 01_start | GO5: -1852.4497 | GP5: -1856.9432 | GQ5: -1856.904 | GR5: -1856.7597 | GS5: -1856.7401 | GT5: -1856.5464 | GU5: -0.039246398 | GV5: =GT5-GU5 -> -1856.5072 | GW5: ∆E#rev | GX5: =627.5095*(GO6-GO4) -> 34.291579 | GY5: =627.5095*(GV6-GV4) -> 10.025891 | GZ5: =627.5095*(GT6-GT4) -> 9.4085986 | HA5: =627.5095*(GS6-GS4) -> 17.598785 | HB5: =627.5095*(GR6-GR4) -> 17.290139 | HC5: =627.5095*(GQ6-GQ4) -> 14.477149 | HD5: =627.5095*(GP6-GP4) -> 13.859857 | HE5: =HD5-GZ5 -> 4.4512584 | HF5: =HD5-HB5 -> -3.4302816 | HG5: =GD5-HF5 -> -0.077348911 | HH5: =GX5-'CCSD(T)'!BB5 -> -0.0040419142 | HI5: =GZ5-'CCSD(T)'!BC5 -> -0.016551074 | HJ5: =HB5-'CCSD(T)'!BD5 -> -0.41068345 | HK5: =HD5-'CCSD(T)'!BE5 -> -0.16286211 | HL5: =HD5-'DLPNO-CCSD(T1 or T0)'!CT4 -> -4.015708 | HM5: =HJ5-HH5 -> -0.40664153 | HN5: =HK5-HJ5 -> 0.24782134 | HP5: 01_start | HQ5: -1852.4497 | HR5: -1856.9444 | HS5: -1856.906 | HT5: -1856.7609 | HU5: -1856.7418 | HV5: -1856.548 | HW5: -0.038343102 | HX5: =HV5-HW5 -> -1856.5097 | HY5: ∆E#rev | HZ5: =627.5095*(HQ6-HQ4) -> 34.291579 | IA5: =627.5095*(HX6-HX4) -> 9.9385637 | IB5: =627.5095*(HV6-HV4) -> 9.3350905 | IC5: =627.5095*(HU6-HU4) -> 17.592992 | ID5: =627.5095*(HT6-HT4) -> 17.291255 | IE5: =627.5095*(HS6-HS4) -> 14.448551 | IF5: =627.5095*(HR6-HR4) -> 13.845077 | IG5: =IF5-IB5 -> 4.5099869 | IH5: =IF5-ID5 -> -3.4461775 | II5: =IH5-HF5 -> -0.015895895 | IJ5: =HZ5-'CCSD(T)'!BB5 -> -0.0040419079 | IK5: =IB5-'CCSD(T)'!BC5 -> -0.090059169 | IL5: =ID5-'CCSD(T)'!BD5 -> -0.40956717 | IM5: =IF5-'CCSD(T)'!BE5 -> -0.17764173 | IN5: =IF5-'DLPNO-CCSD(T1 or T0)'!CT4 -> -4.0304876 | IO5: =IL5-IJ5 -> -0.40552526 | IP5: =IM5-IL5 -> 0.23192544 | IR5: 01_start | IS5: -1852.4497 | IT5: -1856.942 | IU5: -1856.9377 | IV5: -1856.7645 | IW5: -1856.7623 | IX5: -1856.5488 | IY5: -0.0043315449 | IZ5: =IX5-IY5 -> -1856.5445 | JA5: ∆E#rev | JB5: =627.5095*(IS6-IS4) -> 34.291579 | JC5: =627.5095*(IZ6-IZ4) -> 9.4848407 | JD5: =627.5095*(IX6-IX4) -> 9.4124458 | JE5: =627.5095*(IW6-IW4) -> 17.653879 | JF5: =627.5095*(IV6-IV4) -> 17.617681 | JG5: =627.5095*(IU6-IU4) -> 14.107944 | JH5: =627.5095*(IT6-IT4) -> 14.035549 | JI5: =JH5-JD5 -> 4.6231031 | JJ5: =JH5-JF5 -> -3.5821323 | JK5: =JJ5-FC5 -> -0.076675624 | JL5: =JB5-'CCSD(T)'!BB5 -> -0.0040419456 | JM5: =JD5-'CCSD(T)'!BC5 -> -0.012703833 | JN5: =JF5-'CCSD(T)'!BD5 -> -0.083140845 | JO5: =JH5-'CCSD(T)'!BE5 -> 0.012829787 | JP5: =JH5-'DLPNO-CCSD(T1 or T0)'!CT4 -> -3.8400161 | JQ5: =JN5-JL5 -> -0.0790989 | JR5: =JO5-JN5 -> 0.095970632 | JT5: -1859.2021 | JU5: -1858.8594 | JV5: -1858.8574 | JX5: 01_start | JY5: -1853.7137 | JZ5: -1859.1142 | KA5: -1859.0916 | KB5: -1858.8551 | KC5: -1858.8438 | KD5: -1858.7119 | KE5: -0.022614304 | KF5: =KD5-KE5 -> -1858.6893 | KG5: -1858.7377 | KH5: -1858.7377 | KI5: -1858.9854 | KJ5: -1.253265 | KK5: -3.7452306 | KL5: =1.2*KK5+(1/3)*KJ5+JY5 -> -1858.6257 | KM5: =1.3*KK5+JY5 -> -1858.5825 | KN5: =627.5095*(JY6-JY4) -> 34.276653 | KO5: =627.5095*(KF6-KF4) -> 9.5276451 | KP5: =627.5095*(KL6-KL4) -> 14.470096 | KQ5: =627.5095*(KM6-KM4) -> 17.17307 | KR5: =627.5095*(KD6-KD4) -> 9.1048555 | KS5: =627.5095*(KC6-KC4) -> 18.034294 | KT5: =627.5095*(KB6-KB4) -> 17.822899 | KU5: =627.5095*(KA6-KA4) -> 14.332788 | KV5: =627.5095*(JZ6-JZ4) -> 13.909999 | KW5: =KV5-KR5 -> 4.8051431 | KX5: =627.5095*(JT6-JT4) -> 14.717801 | KY5: =627.5095*(JU6-JU4) -> 15.74827 | KZ5: =627.5095*(JV6-JV4) -> 15.800275 | LA5: =KV5-KT5 -> -3.9129005 | LB5: =LA5-GD5 -> -0.40526999 | LC5: =KN5-'PNO-LCCSD(T)'!AB4 -> -0.0025632068 | LD5: =KV5-GB5 -> -0.088640053 | LE5: =KX5-KV5 -> 0.80780272 | LF5: =KY5-KX5 -> 1.0304684 | LG5: =AD5 -> 01_start | LH5: =627.5095*(KG6-KG4) -> 18.332098 | LI5: =KS5-LH5 -> -0.2978038 | LJ5: =KT5-LH5 -> -0.5091986 | LK5: =627.5095*(KI6-KI4) -> 14.619682 | LL5: =KU5-LK5 -> -0.28689369 | LM5: =KV5-LK5 -> -0.70968329 | LN5: =AP5-KS5 -> 3.0326583 | LP5: 01_start | LQ5: -1853.7137 | LR5: -1859.114 | LS5: -1859.0912 | LT5: -1858.8548 | LU5: -1858.8434 | LV5: -1858.7116 | LW5: -0.022811084 | LX5: =LV5-LW5 -> -1858.6888 | LY5: ∆E#rev | LZ5: =627.5095*(LQ6-LQ4) -> 34.276654 | MA5: =627.5095*(LX6-LX4) -> 9.528864 | MB5: =627.5095*(LV6-LV4) -> 9.0987487 | MC5: =627.5095*(LU6-LU4) -> 18.033407 | MD5: =627.5095*(LT6-LT4) -> 17.818349 | ME5: =627.5095*(LS6-LS4) -> 14.333727 | MF5: =627.5095*(LR6-LR4) -> 13.903611 | MG5: =MF5-MB5 -> 4.8048627 | MH5: =MF5-MD5 -> -3.9147379 | MJ5: 01_start | MK5: -1853.7137 | ML5: -1859.1145 | MM5: -1859.0548 | MN5: -1858.8496 | MO5: -1858.8197 | MP5: -1858.7094 | MQ5: -0.059770522 | MR5: =MP5-MQ5 -> -1858.6497 | MS5: ∆E#rev | MT5: =627.5095*(MK6-MK4) -> 34.276653 | MU5: =627.5095*(MR6-MR4) -> 10.257404 | MV5: =627.5095*(MP6-MP4) -> 9.1874329 | MW5: =627.5095*(MO6-MO4) -> 18.280411 | MX5: =627.5095*(MN6-MN4) -> 17.745425 | MY5: =627.5095*(MM6-MM4) -> 14.967136 | MZ5: =627.5095*(ML6-ML4) -> 13.897164 | NA5: =MZ5-MV5 -> 4.7097313 | NB5: =MZ5-MX5 -> -3.8482608 | NC5: =LA5-NB5 -> -0.064639791 | NE5: 01_start | NF5: -1853.7137 | NG5: -1859.1161 | NH5: -1859.0571 | NI5: -1858.8512 | NJ5: -1858.8217 | NK5: -1858.7114 | NL5: -0.058956854 | NM5: =NK5-NL5 -> -1858.6524 | NN5: ∆E#rev | NO5: =627.5095*(NF6-NF4) -> 34.276653 | NP5: =627.5095*(NM6-NM4) -> 10.165843 | NQ5: =627.5095*(NK6-NK4) -> 9.1046979 | NR5: =627.5095*(NJ6-NJ4) -> 18.255088 | NS5: =627.5095*(NI6-NI4) -> 17.724515 | NT5: =627.5095*(NH6-NH4) -> 14.897163 | NU5: =627.5095*(NG6-NG4) -> 13.836019 | NV5: =NU5-NQ5 -> 4.7313206 | NW5: =NU5-NS5 -> -3.8884968 | NX5: =NW5-NB5 -> -0.040236091 | NZ5: 01_start | OA5: -1853.773 | OB5: -1859.4786 | OC5: -1859.3949 | OD5: -1859.1836 | OE5: -1859.1418 | OF5: -1859.0986 | OG5: -0.083683719 | OH5: =OF5-OG5 -> -1859.0149 | OI5: ∆E#rev | OJ5: =627.5095*(OA6-OA4) -> 34.392759 | OK5: =627.5095*(OH6-OH4) -> 10.851791 | OL5: =627.5095*(OF6-OF4) -> 9.4917427 | OM5: =627.5095*(OE6-OE4) -> 18.951395 | ON5: =627.5095*(OD6-OD4) -> 18.271371 | OO5: =627.5095*(OC6-OC4) -> 15.626422 | OP5: =627.5095*(OB6-OB4) -> 14.266374 | OQ5: =OP5-OL5 -> 4.7746312 | OR5: =OP5-ON5 -> -4.0049973 | OT5: 01_start | OU5: -1853.773 | OV5: -1859.4753 | OW5: -1859.4424 | OX5: -1859.1907 | OY5: -1859.1742 | OZ5: -1859.1008 | PA5: -0.032821486 | PB5: -1859.068 | PC5: ∆E#rev | PD5: 34.392759 | PE5: 9.9901302 | PF5: 9.3820672 | PG5: 18.609526 | PH5: 18.305495 | PI5: 14.892342 | PJ5: 14.284279 | PK5: 4.9022115 | PL5: -4.0212159 | PO5: =OJ5-MT5 -> 0.11610547 | PP5: =ON5-MX5 -> 0.52594623 | PQ5: =PP5-PO5 -> 0.40984076 | PR5: ='LNO-CCSD(T)-def2nZVP'!LB5 -> -0.40526999 | PS5: =PO$2*PO5+PQ$2*PQ5 -> 0.31957774 | PT5: =PR5*PR$2 -> -0.24618847 | PU5: =-'LNO-CCSD(T)-def2nZVP'!FA5+'CCSD(T)'!CI5 -> 0.03498756 | PV5: ='LNO-CCSD(T)-def2nZVP'!KV5+PS5+PT5+PU5 -> 14.018375 | PX5: 0.11610487 | PY5: 0.48714544 | PZ5: 0.37104057 | QA5: -0.40526999 | QB5: 0.29083679 | QC5: -0.24618847 | QD5: 0.03498756 | QE5: 13.989634 | QF5: =QE5-PV5 -> -0.028740945 | QH5: 01_start | QI5: -1853.7137 | QJ5: -1858.8669 | QK5: -1858.846 | QL5: -1858.6169 | QM5: -1858.6065 | QN5: -1858.4811 | QO5: -0.020928338 | QP5: =QN5-QO5 -> -1858.4601 | QQ5: ∆E#rev | QR5: =627.5095*(QI6-QI4) -> 34.276654 | QS5: =627.5095*(QP6-QP4) -> 11.951789 | QT5: =627.5095*(QN6-QN4) -> 11.568069 | QU5: =627.5095*(QM6-QM4) -> 19.633547 | QV5: =627.5095*(QL6-QL4) -> 19.441687 | QW5: =627.5095*(QK6-QK4) -> 16.105316 | QX5: =627.5095*(QJ6-QJ4) -> 15.721595 | QY5: =QX5-QT5 -> 4.1535266 | QZ5: =QX5-QV5 -> -3.7200919 | RB5: 01_start | RC5: -1853.773 | RD5: -1859.1776 | RE5: -1859.1471 | RF5: -1858.9061 | RG5: -1858.8908 | RH5: -1858.8272 | RI5: -0.030504702 | RJ5: =RH5-RI5 -> -1858.7967 | RK5: ∆E#rev | RL5: =627.5095*(RC6-RC4) -> 34.392759 | RM5: =627.5095*(RJ6-RJ4) -> 12.212377 | RN5: =627.5095*(RH6-RH4) -> 11.695265 | RO5: =627.5095*(RG6-RG4) -> 19.959448 | RP5: =627.5095*(RF6-RF4) -> 19.700892 | RQ5: =627.5095*(RE6-RE4) -> 16.411416 | RR5: =627.5095*(RD6-RD4) -> 15.894304 | RS5: =RR5-RN5 -> 4.1990393 | RT5: =RR5-RP5 -> -3.8065875
A6: 10.63 | C6: 01_ts | D6: -1852.2668 | E6: -1856.4653 | F6: -1856.4522 | G6: -1856.2978 | H6: -1856.2913 | I6: -1856.0982 | J6: -1856.0852 | K6: ∆Ereac | L6: =627.5095*(D4-D5) -> 6.741893 | M6: =627.5095*(J4-J5) -> 14.797812 | N6: =627.5095*(I4-I5) -> 15.049972 | O6: =627.5095*(H4-H5) -> 12.151859 | P6: =627.5095*(G4-G5) -> 12.277939 | Q6: =627.5095*(F4-F5) -> 13.045976 | R6: =627.5095*(E4-E5) -> 13.298137 | S6: =R6-N6 -> -1.7518356 | T6: =R6-P6 -> 1.0201975 | V6: =L6-'CCSD(T)'!BV6 -> -0.0011641431 | W6: =N6-'CCSD(T)'!BW6 -> -0.036291666 | X6: =P6-'CCSD(T)'!BX6 -> 0.049197788 | Y6: =R6-'CCSD(T)'!BY6 -> 0.028321537 | Z6: =R6-'DLPNO-CCSD(T1 or T0)'!CT5 -> 0.050812337 | AA6: =X6-V6 -> 0.050361932 | AB6: =Y6-X6 -> -0.020876252 | AD6: 01_ts | AE6: -1852.2668 | AF6: -1856.4655 | AG6: -1856.4525 | AH6: -1856.298 | AI6: -1856.2915 | AJ6: -1856.0985 | AK6: -1856.0855 | AL6: ∆Ereac | AM6: =627.5095*(AE4-AE5) -> 6.741893 | AN6: =627.5095*(AK4-AK5) -> 14.772585 | AO6: =627.5095*(AJ4-AJ5) -> 15.039424 | AP6: =627.5095*(AI4-AI5) -> 12.136352 | AQ6: =627.5095*(AH4-AH5) -> 12.269772 | AR6: =627.5095*(AG4-AG5) -> 13.024157 | AS6: =627.5095*(AF4-AF5) -> 13.290996 | AT6: =AS6-AO6 -> -1.7484281 | AU6: =AS6-AQ6 -> 1.0212248 | AW6: =AM6-'CCSD(T)'!BV6 -> -0.0011641431 | AX6: =AO6-'CCSD(T)'!BW6 -> -0.046839329 | AY6: =AQ6-'CCSD(T)'!BX6 -> 0.041030413 | AZ6: =AS6-'CCSD(T)'!BY6 -> 0.021181382 | BA6: =AS6-'DLPNO-CCSD(T1 or T0)'!CT5 -> 0.043672183 | BB6: =AY6-AW6 -> 0.042194557 | BC6: =AZ6-AY6 -> -0.019849031 | BE6: 01_ts | BF6: -1852.2668 | BG6: -1856.4662 | BH6: -1856.4307 | BI6: -1856.2945 | BJ6: -1856.2767 | BK6: -1856.0969 | BL6: -0.035542678 | BM6: =BK6-BL6 -> -1856.0614 | BN6: ∆Ereac | BO6: =627.5095*(BF4-BF5) -> 6.741893 | BP6: =627.5095*(BM4-BM5) -> 14.10507 | BQ6: =627.5095*(BK4-BK5) -> 14.939859 | BR6: =627.5095*(BJ4-BJ5) -> 11.796619 | BS6: =627.5095*(BI4-BI5) -> 12.214014 | BT6: =627.5095*(BH4-BH5) -> 12.503187 | BU6: =627.5095*(BG4-BG5) -> 13.337976 | BV6: =BU6-BQ6 -> -1.6018831 | BW6: =BU6-BS6 -> 1.1239621 | BX6: =AU6-BW6 -> -0.10273734 | BY6: =BO6-'CCSD(T)'!BV6 -> -0.0011641305 | BZ6: =BQ6-'CCSD(T)'!BW6 -> -0.14640509 | CA6: =BS6-'CCSD(T)'!BX6 -> -0.01472769 | CB6: =BU6-'CCSD(T)'!BY6 -> 0.068160621 | CC6: =BU6-'DLPNO-CCSD(T1 or T0)'!CT5 -> 0.090651422 | CD6: =CA6-BY6 -> -0.013563559 | CE6: =CB6-CA6 -> 0.082888311 | CG6: 01_ts | CH6: -1852.2668 | CI6: -1856.4672 | CJ6: -1856.4324 | CK6: -1856.2956 | CL6: -1856.2782 | CM6: -1856.0984 | CN6: -0.034784324 | CO6: =CM6-CN6 -> -1856.0636 | CP6: ∆Ereac | CQ6: =627.5095*(CH4-CH5) -> 6.741893 | CR6: =627.5095*(CO4-CO5) -> 14.306223 | CS6: =627.5095*(CM4-CM5) -> 15.017875 | CT6: =627.5095*(CL4-CL5) -> 11.891336 | CU6: =627.5095*(CK4-CK5) -> 12.247162 | CV6: =627.5095*(CJ4-CJ5) -> 12.620447 | CW6: =627.5095*(CI4-CI5) -> 13.332099 | CX6: =CW6-CS6 -> -1.6857761 | CY6: =CW6-CU6 -> 1.0849372 | CZ6: =CY6-BW6 -> -0.03902491 | DA6: =CQ6-'CCSD(T)'!BV6 -> -0.0011641431 | DB6: =CS6-'CCSD(T)'!BW6 -> -0.068388545 | DC6: =CU6-'CCSD(T)'!BX6 -> 0.018420819 | DD6: =CW6-'CCSD(T)'!BY6 -> 0.062284221 | DE6: =CW6-'DLPNO-CCSD(T1 or T0)'!CT5 -> 0.084775021 | DF6: =DC6-DA6 -> 0.019584962 | DG6: =DD6-DC6 -> 0.043863402 | DI6: 01_ts | DJ6: -1852.2668 | DK6: -1856.4643 | DL6: -1856.4606 | DM6: -1856.2984 | DN6: -1856.2965 | DO6: -1856.0989 | DP6: -0.0037260793 | DQ6: =DO6-DP6 -> -1856.0952 | DR6: ∆Ereac | DS6: =627.5095*(DJ4-DJ5) -> 6.741893 | DT6: =627.5095*(DQ4-DQ5) -> 15.086261 | DU6: =627.5095*(DO4-DO5) -> 15.117954 | DV6: =627.5095*(DN4-DN5) -> 12.249215 | DW6: =627.5095*(DM4-DM5) -> 12.265062 | DX6: =627.5095*(DL4-DL5) -> 13.215769 | DY6: =627.5095*(DK4-DK5) -> 13.247463 | DZ6: =DY6-DU6 -> -1.8704912 | EA6: =DY6-DW6 -> 0.98240094 | EB6: =EA6-T6 -> -0.037796598 | EC6: =DS6-'CCSD(T)'!BV6 -> -0.0011641494 | ED6: =DU6-'CCSD(T)'!BW6 -> 0.031689996 | EE6: =DW6-'CCSD(T)'!BX6 -> 0.036320434 | EF6: =DY6-'CCSD(T)'!BY6 -> -0.022352415 | EG6: =DY6-'DLPNO-CCSD(T1 or T0)'!CT5 -> 0.00013838464 | EH6: =EE6-EC6 -> 0.037484583 | EI6: =EF6-EE6 -> -0.058672849 | EK6: 01_ts | EL6: -1852.3843 | EM6: -1856.8993 | EN6: -1856.8854 | EO6: -1856.7166 | EP6: -1856.7097 | EQ6: -1856.5091 | ER6: -0.013888228 | ES6: =EQ6-ER6 -> -1856.4952 | ET6: ∆Ereac | EU6: =627.5095*(EL4-EL5) -> 6.6941564 | EV6: =627.5095*(ES4-ES5) -> 14.745916 | EW6: =627.5095*(EQ4-EQ5) -> 14.976875 | EX6: =627.5095*(EP4-EP5) -> 11.851145 | EY6: =627.5095*(EO4-EO5) -> 11.966624 | EZ6: =627.5095*(EN4-EN5) -> 12.829593 | FA6: =627.5095*(EM4-EM5) -> 13.060552 | FB6: =FA6-EW6 -> -1.9163225 | FC6: =FA6-EY6 -> 1.093928 | FD6: =EU6-'CCSD(T)'!BB6 -> 0.0011531869 | FE6: =EW6-'CCSD(T)'!BC6 -> -0.018541516 | FF6: =EY6-'CCSD(T)'!CH6 -> 0.072735392 | FG6: =FA6-'CCSD(T)'!CI6 -> 0.019839266 | FH6: =FA6-'DLPNO-CCSD(T1 or T0)'!AF5 -> 0.13942928 | FI6: =FF6-FD6 -> 0.071582205 | FJ6: =FG6-FF6 -> -0.052896126 | FL6: 01_ts | FM6: -1852.3843 | FN6: -1856.8995 | FO6: -1856.8857 | FP6: -1856.7168 | FQ6: -1856.7099 | FR6: -1856.5094 | FS6: -0.013785011 | FT6: =FR6-FS6 -> -1856.4956 | FU6: ∆Ereac | FV6: =627.5095*(FM4-FM5) -> 6.6941564 | FW6: =627.5095*(FT4-FT5) -> 14.743083 | FX6: =627.5095*(FR4-FR5) -> 14.969399 | FY6: =627.5095*(FQ4-FQ5) -> 11.845544 | FZ6: =627.5095*(FP4-FP5) -> 11.958702 | GA6: =627.5095*(FO4-FO5) -> 12.832056 | GB6: =627.5095*(FN4-FN5) -> 13.058372 | GC6: =GB6-FX6 -> -1.9110268 | GD6: =GB6-FZ6 -> 1.0996699 | GE6: =LA6-GD6 -> 0.028256916 | GF6: =FV6-'CCSD(T)'!BB6 -> 0.0011531367 | GG6: =FX6-'CCSD(T)'!BC6 -> -0.026017112 | GH6: =FZ6-'CCSD(T)'!BD6 -> 0.06481365 | GI6: =GB6-'CCSD(T)'!BE6 -> 0.017659367 | GJ6: =GB6-'DLPNO-CCSD(T1 or T0)'!O5 -> 0.07034871 | GK6: =GH6-GF6 -> 0.063660513 | GL6: =GI6-GH6 -> -0.047154282 | GN6: 01_ts | GO6: -1852.3843 | GP6: -1856.9003 | GQ6: -1856.8614 | GR6: -1856.7132 | GS6: -1856.6938 | GT6: -1856.5078 | GU6: -0.038854907 | GV6: =GT6-GU6 -> -1856.4689 | GW6: ∆Ereac | GX6: =627.5095*(GO4-GO5) -> 6.6941564 | GY6: =627.5095*(GV4-GV5) -> 14.001235 | GZ6: =627.5095*(GT4-GT5) -> 14.864192 | HA6: =627.5095*(GS4-GS5) -> 11.463629 | HB6: =627.5095*(GR4-GR5) -> 11.895107 | HC6: =627.5095*(GQ4-GQ5) -> 12.232734 | HD6: =627.5095*(GP4-GP5) -> 13.095691 | HE6: =HD6-GZ6 -> -1.7685006 | HF6: =HD6-HB6 -> 1.2005835 | HG6: =GD6-HF6 -> -0.10091367 | HH6: =GX6-'CCSD(T)'!BB6 -> 0.0011531492 | HI6: =GZ6-'CCSD(T)'!BC6 -> -0.13122457 | HJ6: =HB6-'CCSD(T)'!BD6 -> 0.0012187872 | HK6: =HD6-'CCSD(T)'!BE6 -> 0.054978179 | HL6: =HD6-'DLPNO-CCSD(T1 or T0)'!CT5 -> -0.15163321 | HM6: =HJ6-HH6 -> 6.563797e-05 | HN6: =HK6-HJ6 -> 0.053759392 | HP6: 01_ts | HQ6: -1852.3843 | HR6: -1856.9013 | HS6: -1856.8633 | HT6: -1856.7143 | HU6: -1856.6953 | HV6: -1856.5093 | HW6: -0.038074372 | HX6: =HV6-HW6 -> -1856.4712 | HY6: ∆Ereac | HZ6: =627.5095*(HQ4-HQ5) -> 6.6941564 | IA6: =627.5095*(HX4-HX5) -> 14.194639 | IB6: =627.5095*(HV4-HV5) -> 14.966743 | IC6: =627.5095*(HU4-HU5) -> 11.561431 | ID6: =627.5095*(HT4-HT5) -> 11.947483 | IE6: =627.5095*(HS4-HS5) -> 12.374437 | IF6: =627.5095*(HR4-HR5) -> 13.146542 | IG6: =IF6-IB6 -> -1.8202019 | IH6: =IF6-ID6 -> 1.1990581 | II6: =IH6-HF6 -> -0.0015254442 | IJ6: =HZ6-'CCSD(T)'!BB6 -> 0.001153143 | IK6: =IB6-'CCSD(T)'!BC6 -> -0.028672645 | IL6: =ID6-'CCSD(T)'!BD6 -> 0.053594778 | IM6: =IF6-'CCSD(T)'!BE6 -> 0.10582873 | IN6: =IF6-'DLPNO-CCSD(T1 or T0)'!CT5 -> -0.10078266 | IO6: =IL6-IJ6 -> 0.052441635 | IP6: =IM6-IL6 -> 0.052233948 | IR6: 01_ts | IS6: -1852.3843 | IT6: -1856.8989 | IU6: -1856.8946 | IV6: -1856.7174 | IW6: -1856.7153 | IX6: -1856.5099 | IY6: -0.0043333001 | IZ6: =IX6-IY6 -> -1856.5055 | JA6: ∆Ereac | JB6: =627.5095*(IS4-IS5) -> 6.6941564 | JC6: =627.5095*(IZ4-IZ5) -> 14.940986 | JD6: =627.5095*(IX4-IX5) -> 15.012279 | JE6: =627.5095*(IW4-IW5) -> 11.884757 | JF6: =627.5095*(IV4-IV5) -> 11.920404 | JG6: =627.5095*(IU4-IU5) -> 12.930994 | JH6: =627.5095*(IT4-IT5) -> 13.002288 | JI6: =JH6-JD6 -> -2.0099919 | JJ6: =JH6-JF6 -> 1.0818834 | JK6: =JJ6-FC6 -> -0.01204458 | JL6: =JB6-'CCSD(T)'!BB6 -> 0.0011531806 | JM6: =JD6-'CCSD(T)'!BC6 -> 0.016863379 | JN6: =JF6-'CCSD(T)'!BD6 -> 0.026515484 | JO6: =JH6-'CCSD(T)'!BE6 -> -0.038425223 | JP6: =JH6-'DLPNO-CCSD(T1 or T0)'!CT5 -> -0.24503661 | JQ6: =JN6-JL6 -> 0.025362303 | JR6: =JO6-JN6 -> -0.064940707 | JT6: -1859.1598 | JU6: -1858.8139 | JV6: -1858.8118 | JX6: 01_ts | JY6: -1853.6481 | JZ6: -1859.0716 | KA6: -1859.0488 | KB6: -1858.808 | KC6: -1858.7967 | KD6: -1858.6738 | KE6: -0.02274912 | KF6: =KD6-KE6 -> -1858.6511 | KG6: -1858.6905 | KH6: -1858.6905 | KI6: -1858.9425 | KJ6: -1.2661176 | KK6: -3.7599875 | KL6: =1.2*KK6+(1/3)*KJ6+JY6 -> -1858.5821 | KM6: =1.3*KK6+JY6 -> -1858.5361 | KN6: =627.5095*(JY4-JY5) -> 6.8732564 | KO6: =627.5095*(KF4-KF5) -> 14.445598 | KP6: =627.5095*(KL4-KL5) -> 12.879358 | KQ6: =627.5095*(KM4-KM5) -> 11.938758 | KR6: =627.5095*(KD4-KD5) -> 14.783789 | KS6: =627.5095*(KC4-KC5) -> 11.542751 | KT6: =627.5095*(KB4-KB5) -> 11.711846 | KU6: =627.5095*(KA4-KA5) -> 12.501582 | KV6: =627.5095*(JZ4-JZ5) -> 12.839773 | KW6: =KV6-KR6 -> -1.9440161 | KX6: =627.5095*(JT4-JT5) -> 11.829679 | KY6: =627.5095*(JU4-JU5) -> 12.788264 | KZ6: =627.5095*(JV4-JV5) -> 12.823243 | LA6: =KV6-KT6 -> 1.1279268 | LB6: =LA6-GD6 -> 0.028256916 | LC6: =KN6-'PNO-LCCSD(T)'!AB5 -> -0.0013132582 | LD6: =KV6-GB6 -> -0.21859913 | LE6: =KX6-KV6 -> -1.0100945 | LF6: =KY6-KX6 -> 0.95858557 | LG6: =AD6 -> 01_ts | LH6: =627.5095*(KG4-KG5) -> 11.267057 | LI6: =KS6-LH6 -> 0.27569338 | LJ6: =KT6-LH6 -> 0.44478894 | LK6: =627.5095*(KI4-KI5) -> 12.258376 | LL6: =KU6-LK6 -> 0.24320581 | LM6: =KV6-LK6 -> 0.58139692 | LN6: =AP6-KS6 -> 0.59360141 | LP6: 01_ts | LQ6: -1853.6481 | LR6: -1859.0713 | LS6: -1859.0484 | LT6: -1858.8078 | LU6: -1858.7963 | LV6: -1858.6735 | LW6: -0.022945614 | LX6: =LV6-LW6 -> -1858.6506 | LY6: ∆Ereac | LZ6: =627.5095*(LQ4-LQ5) -> 6.873256 | MA6: =627.5095*(LX4-LX5) -> 14.448427 | MB6: =627.5095*(LV4-LV5) -> 14.794123 | MC6: =627.5095*(LU4-LU5) -> 11.545447 | MD6: =627.5095*(LT4-LT5) -> 11.718295 | ME6: =627.5095*(LS4-LS5) -> 12.502651 | MF6: =627.5095*(LR4-LR5) -> 12.848348 | MG6: =MF6-MB6 -> -1.9457755 | MH6: =MF6-MD6 -> 1.1300529 | MJ6: 01_ts | MK6: -1853.6481 | ML6: -1859.0719 | MM6: -1859.0121 | MN6: -1858.8028 | MO6: -1858.7729 | MP6: -1858.6714 | MQ6: -0.059780327 | MR6: =MP6-MQ6 -> -1858.6117 | MS6: ∆Ereac | MT6: =627.5095*(MK4-MK5) -> 6.8732564 | MU6: =627.5095*(MR4-MR5) -> 13.585617 | MV6: =627.5095*(MP4-MP5) -> 14.649436 | MW6: =627.5095*(MO4-MO5) -> 11.063812 | MX6: =627.5095*(MN4-MN5) -> 11.595722 | MY6: =627.5095*(MM4-MM5) -> 11.805104 | MZ6: =627.5095*(ML4-ML5) -> 12.868923 | NA6: =MZ6-MV6 -> -1.7805132 | NB6: =MZ6-MX6 -> 1.2732012 | NC6: =LA6-NB6 -> -0.1452744 | NE6: 01_ts | NF6: -1853.6481 | NG6: -1859.0734 | NH6: -1859.0144 | NI6: -1858.8043 | NJ6: -1858.7748 | NK6: -1858.6734 | NL6: -0.058951271 | NM6: =NK6-NL6 -> -1858.6144 | NN6: ∆Ereac | NO6: =627.5095*(NF4-NF5) -> 6.8732564 | NP6: =627.5095*(NM4-NM5) -> 13.70782 | NQ6: =627.5095*(NK4-NK5) -> 14.772468 | NR6: =627.5095*(NJ4-NJ5) -> 11.145506 | NS6: =627.5095*(NI4-NI5) -> 11.677829 | NT6: =627.5095*(NH4-NH5) -> 11.90926 | NU6: =627.5095*(NG4-NG5) -> 12.973907 | NV6: =NU6-NQ6 -> -1.79856 | NW6: =NU6-NS6 -> 1.296078 | NX6: =NW6-NB6 -> 0.022876831 | NZ6: 01_ts | OA6: -1853.7073 | OB6: -1859.4369 | OC6: -1859.3527 | OD6: -1859.1375 | OE6: -1859.0954 | OF6: -1859.0615 | OG6: -0.08421833 | OH6: =OF6-OG6 -> -1858.9773 | OI6: ∆Ereac | OJ6: =627.5095*(OA4-OA5) -> 6.7870039 | OK6: =627.5095*(OH4-OH5) -> 12.724414 | OL6: =627.5095*(OF4-OF5) -> 13.748988 | OM6: =627.5095*(OE4-OE5) -> 10.133552 | ON6: =627.5095*(OD4-OD5) -> 10.645839 | OO6: =627.5095*(OC4-OC5) -> 10.848508 | OP6: =627.5095*(OB4-OB5) -> 11.873082 | OQ6: =OP6-OL6 -> -1.8759059 | OR6: =OP6-ON6 -> 1.2272431 | OT6: 01_ts | OU6: -1853.7073 | OV6: -1859.4336 | OW6: -1859.4004 | OX6: -1859.1443 | OY6: -1859.1278 | OZ6: -1859.0637 | PA6: -0.033132645 | PB6: -1859.0306 | PC6: ∆Ereac | PD6: 6.7870033 | PE6: 13.477153 | PF6: 13.889961 | PG6: 10.548757 | PH6: 10.755161 | PI6: 11.474888 | PJ6: 11.887696 | PK6: -2.0022648 | PL6: 1.1325347 | PO6: =OJ6-MT6 -> -0.086252492 | PP6: =ON6-MX6 -> -0.94988234 | PQ6: =PP6-PO6 -> -0.86362985 | PR6: ='LNO-CCSD(T)-def2nZVP'!LB6 -> 0.028256916 | PS6: =PO$2*PO6+PQ$2*PQ6 -> -0.65160564 | PT6: =PR6*PR$2 -> 0.017165166 | PU6: =-'LNO-CCSD(T)-def2nZVP'!FA6+'CCSD(T)'!CI6 -> -0.019839266 | PV6: ='LNO-CCSD(T)-def2nZVP'!KV6+PS6+PT6+PU6 -> 12.185493 | PX6: -0.086252668 | PY6: -0.96313378 | PZ6: -0.87688111 | QA6: 0.028256916 | QB6: -0.66142141 | QC6: 0.017165166 | QD6: -0.019839266 | QE6: 12.175678 | QF6: =QE6-PV6 -> -0.0098157669 | QH6: 01_ts | QI6: -1853.6481 | QJ6: -1858.821 | QK6: -1858.8 | QL6: -1858.5669 | QM6: -1858.5564 | QN6: -1858.4388 | QO6: -0.021034684 | QP6: =QN6-QO6 -> -1858.4178 | QQ6: ∆Ereac | QR6: =627.5095*(QI4-QI5) -> 6.873256 | QS6: =627.5095*(QP4-QP5) -> 14.639573 | QT6: =627.5095*(QN4-QN5) -> 14.956561 | QU6: =627.5095*(QM4-QM5) -> 11.784821 | QV6: =627.5095*(QL4-QL5) -> 11.943315 | QW6: =627.5095*(QK4-QK5) -> 12.787386 | QX6: =627.5095*(QJ4-QJ5) -> 13.104373 | QY6: =QX6-QT6 -> -1.8521874 | QZ6: =QX6-QV6 -> 1.1610587 | RB6: 01_ts | RC6: -1853.7073 | RD6: -1859.1318 | RE6: -1859.1011 | RF6: -1858.856 | RG6: -1858.8407 | RH6: -1858.785 | RI6: -0.03073094 | RJ6: =RH6-RI6 -> -1858.7543 | RK6: ∆Ereac | RL6: =627.5095*(RC4-RC5) -> 6.7870037 | RM6: =627.5095*(RJ4-RJ5) -> 14.362819 | RN6: =627.5095*(RH4-RH5) -> 14.737964 | RO6: =627.5095*(RG4-RG5) -> 11.502833 | RP6: =627.5095*(RF4-RF5) -> 11.690406 | RQ6: =627.5095*(RE4-RE5) -> 12.490201 | RR6: =627.5095*(RD4-RD5) -> 12.865346 | RS6: =RR6-RN6 -> -1.8726186 | RT6: =RR6-RP6 -> 1.1749399
